####### Athlete 1


####### Athlete 2


####### Athlete 3


####### Athlete 4

2020-09-15-114157-ELEMNT 5F6E-371-0
Traceback (most recent call last):
  File "parse_fit_to_csv.py", line 24, in <module>
    for m in fitfile.messages:
  File "/usr/local/lib/python3.7/dist-packages/fitparse/base.py", line 441, in messages
    return list(self.get_messages())
  File "/usr/local/lib/python3.7/dist-packages/fitparse/base.py", line 434, in get_messages
    message = self._parse_message()
  File "/usr/local/lib/python3.7/dist-packages/fitparse/base.py", line 135, in _parse_message
    self._read_and_assert_crc()
  File "/usr/local/lib/python3.7/dist-packages/fitparse/base.py", line 88, in _read_and_assert_crc
    Crc.format(crc_computed), Crc.format(crc_read)))
fitparse.utils.FitCRCError: CRC Mismatch [computed: 0x0000, read: 0x0040]


####### Athlete 5


####### Athlete 6


####### Athlete 7


####### Athlete 8

2020-02-29-091619-ELEMNT BOLT 62CF-450-0
Traceback (most recent call last):
  File "parse_fit_to_csv.py", line 24, in <module>
    for m in fitfile.messages:
  File "/usr/local/lib/python3.7/dist-packages/fitparse/base.py", line 441, in messages
    return list(self.get_messages())
  File "/usr/local/lib/python3.7/dist-packages/fitparse/base.py", line 434, in get_messages
    message = self._parse_message()
  File "/usr/local/lib/python3.7/dist-packages/fitparse/base.py", line 135, in _parse_message
    self._read_and_assert_crc()
  File "/usr/local/lib/python3.7/dist-packages/fitparse/base.py", line 82, in _read_and_assert_crc
    crc_computed, crc_read = self._crc.value, self._read_struct(Crc.FMT)
  File "/usr/local/lib/python3.7/dist-packages/fitparse/base.py", line 74, in _read_struct
    data = self._read(size)
  File "/usr/local/lib/python3.7/dist-packages/fitparse/base.py", line 60, in _read
    raise FitEOFError("Tried to read %d bytes from .FIT file but got %d" % (size, len(data)))
fitparse.utils.FitEOFError: Tried to read 2 bytes from .FIT file but got 0

2020-08-11-205227-ELEMNT BOLT 62CF-619-0
Traceback (most recent call last):
  File "parse_fit_to_csv.py", line 24, in <module>
    for m in fitfile.messages:
  File "/usr/local/lib/python3.7/dist-packages/fitparse/base.py", line 441, in messages
    return list(self.get_messages())
  File "/usr/local/lib/python3.7/dist-packages/fitparse/base.py", line 434, in get_messages
    message = self._parse_message()
  File "/usr/local/lib/python3.7/dist-packages/fitparse/base.py", line 135, in _parse_message
    self._read_and_assert_crc()
  File "/usr/local/lib/python3.7/dist-packages/fitparse/base.py", line 82, in _read_and_assert_crc
    crc_computed, crc_read = self._crc.value, self._read_struct(Crc.FMT)
  File "/usr/local/lib/python3.7/dist-packages/fitparse/base.py", line 74, in _read_struct
    data = self._read(size)
  File "/usr/local/lib/python3.7/dist-packages/fitparse/base.py", line 60, in _read
    raise FitEOFError("Tried to read %d bytes from .FIT file but got %d" % (size, len(data)))
fitparse.utils.FitEOFError: Tried to read 2 bytes from .FIT file but got 0

2020-08-29-212207-ELEMNT BOLT 62CF-635-0
Traceback (most recent call last):
  File "parse_fit_to_csv.py", line 24, in <module>
    for m in fitfile.messages:
  File "/usr/local/lib/python3.7/dist-packages/fitparse/base.py", line 441, in messages
    return list(self.get_messages())
  File "/usr/local/lib/python3.7/dist-packages/fitparse/base.py", line 434, in get_messages
    message = self._parse_message()
  File "/usr/local/lib/python3.7/dist-packages/fitparse/base.py", line 149, in _parse_message
    message = self._parse_definition_message(header)
  File "/usr/local/lib/python3.7/dist-packages/fitparse/base.py", line 219, in _parse_definition_message
    field = get_dev_type(dev_data_index, field_def_num)
  File "/usr/local/lib/python3.7/dist-packages/fitparse/records.py", line 474, in get_dev_type
    raise FitParseError("No such dev_data_index=%s found when looking up field %s" % (dev_data_index, field_def_num))
fitparse.utils.FitParseError: No such dev_data_index=1 found when looking up field 0

####### Athlete 9


####### Athlete 10

2020-04-05-110931-ELEMNT BOLT 2E46-260-0
Traceback (most recent call last):
  File "parse_fit_to_csv.py", line 24, in <module>
    for m in fitfile.messages:
  File "/usr/local/lib/python3.7/dist-packages/fitparse/base.py", line 441, in messages
    return list(self.get_messages())
  File "/usr/local/lib/python3.7/dist-packages/fitparse/base.py", line 434, in get_messages
    message = self._parse_message()
  File "/usr/local/lib/python3.7/dist-packages/fitparse/base.py", line 149, in _parse_message
    message = self._parse_definition_message(header)
  File "/usr/local/lib/python3.7/dist-packages/fitparse/base.py", line 219, in _parse_definition_message
    field = get_dev_type(dev_data_index, field_def_num)
  File "/usr/local/lib/python3.7/dist-packages/fitparse/records.py", line 474, in get_dev_type
    raise FitParseError("No such dev_data_index=%s found when looking up field %s" % (dev_data_index, field_def_num))
fitparse.utils.FitParseError: No such dev_data_index=1 found when looking up field 0


####### Athlete 11


####### Athlete 12


####### Athlete 13


####### Athlete 14

2020-07-06_12-16-51_9b5203c2-ec3d-4b0c-8fe3-07ea8eae08eb.gz
mv: cannot stat 'Data/TrainingPeaks/raw_anonymous/14/2020-07-06_12-16-51_9b5203c2-ec3d-4b0c-8fe3-07ea8eae08eb.gz.fit': No such file or directory
Traceback (most recent call last):
  File "parse_fit_to_csv.py", line 21, in <module>
    fitfile = fitparse.FitFile(args.input + '/' + args.filename)
  File "/usr/local/lib/python3.7/dist-packages/fitparse/base.py", line 23, in __init__
    self._file = fileish_open(fileish, 'rb')
  File "/usr/local/lib/python3.7/dist-packages/fitparse/utils.py", line 56, in fileish_open
    return open(fileish, mode)
FileNotFoundError: [Errno 2] No such file or directory: 'Data/TrainingPeaks/fit/14//2020-07-06_12-16-51_9b5203c2-ec3d-4b0c-8fe3-07ea8eae08eb.gz.fit'

2020-08-10_17-30-48_359b0bec-f510-4c7a-a527-108ddf3d1dd4.gz
mv: cannot stat 'Data/TrainingPeaks/raw_anonymous/14/2020-08-10_17-30-48_359b0bec-f510-4c7a-a527-108ddf3d1dd4.gz.fit': No such file or directory
Traceback (most recent call last):
  File "parse_fit_to_csv.py", line 21, in <module>
    fitfile = fitparse.FitFile(args.input + '/' + args.filename)
  File "/usr/local/lib/python3.7/dist-packages/fitparse/base.py", line 23, in __init__
    self._file = fileish_open(fileish, 'rb')
  File "/usr/local/lib/python3.7/dist-packages/fitparse/utils.py", line 56, in fileish_open
    return open(fileish, mode)
FileNotFoundError: [Errno 2] No such file or directory: 'Data/TrainingPeaks/fit/14//2020-08-10_17-30-48_359b0bec-f510-4c7a-a527-108ddf3d1dd4.gz.fit'


####### Athlete 15
